Workbook

Sheet Sheet1
A2: Season | B2: Team | C2: Level | D2: Age | E2: G | F2: PA | G2: HR | H2: R | I2: RBI | J2: SB | K2: BB% | L2: K% | M2: ISO | N2: BABIP | O2: AVG | P2: OBP | Q2: SLG | R2: wOBA | S2: xwOBA | T2: wRC+
A3: 2023 | B3: DET | C3: A+ | D3: 23 | E3: 45 | F3: 198 | G3: 6 | H3: 36 | I3: 29 | J3: 8 | K3: 0.086 | L3: 0.283 | M3: 0.147 | N3: 0.388 | O3: 0.288 | P3: 0.355 | Q3: 0.435 | R3: 0.363 | T3: 130
A4: 2023 | B4: DET | C4: AA | D4: 23 | E4: 55 | F4: 214 | G4: 7 | H4: 37 | I4: 19 | J4: 11 | K4: 0.145 | L4: 0.388 | M4: 0.191 | N4: 0.3 | O4: 0.191 | P4: 0.318 | Q4: 0.382 | R4: 0.321 | T4: 97
B6: Weighted | F6: =SUM(F3:F4) -> 412 | K6: =SUM((K3*$F$3)+(K4*$F$4))/412 -> 0.11664563 | L6: =SUM((L3*$F$3)+(L4*$F$4))/412 -> 0.33753883 | M6: =SUM((M3*$F$3)+(M4*$F$4))/412 -> 0.16985437 | N6: =SUM((N3*$F$3)+(N4*$F$4))/412 -> 0.34229126 | O6: =SUM((O3*$F$3)+(O4*$F$4))/412 -> 0.2376165 | P6: =SUM((P3*$F$3)+(P4*$F$4))/412 -> 0.33578155 | Q6: =SUM((Q3*$F$3)+(Q4*$F$4))/412 -> 0.40747087 | R6: =SUM((R3*$F$3)+(R4*$F$4))/412 -> 0.34118447 | T6: =SUM((T3*$F$3)+(T4*$F$4))/412 -> 112.85922
B8: A | C8: 1
B9: A+ | C9: 2
B10: AA | C10: 3
B11: AAA | C11: 4

Sheet Debut Class
A1: Year | B1: PlayerID | C1: Name | D1: Team | E1: G | F1: PA | G1: HR | H1: R | I1: RBI | J1: SB | K1: BB% | L1: K% | M1: ISO | N1: BABIP | O1: AVG | P1: OBP | Q1: SLG | R1: wOBA | S1: xwOBA | T1: wRC+ | U1: BsR | V1: Off | W1: Def | X1: WAR
A2: 2023 | B2: =_xlfn.XLOOKUP(C2,ID!$J$2:$J$3825,ID!$I$2:$I$3825,"n/a",0,1) -> 25878 | C2: Corbin Carroll | D2: ARI | E2: 155 | F2: 645 | G2: 25 | H2: 116 | I2: 76 | J2: 54 | K2: 0.088 | L2: 0.194 | M2: 0.221 | N2: 0.325 | O2: 0.285 | P2: 0.362 | Q2: 0.506 | R2: 0.37 | S2: 0.345 | T2: 133 | U2: 12.3 | V2: 38.3 | W2: -6.6 | X2: 5.3
A3: 2023 | B3: =_xlfn.XLOOKUP(C3,ID!$J$2:$J$3825,ID!$I$2:$I$3825,"n/a",0,1) -> 26289 | C3: Gunnar Henderson | D3: BAL | E3: 150 | F3: 622 | G3: 28 | H3: 100 | I3: 82 | J3: 10 | K3: 0.09 | L3: 0.256 | M3: 0.234 | N3: 0.306 | O3: 0.255 | P3: 0.325 | Q3: 0.489 | R3: 0.346 | S3: 0.346 | T3: 122 | U3: 5.8 | V3: 22.3 | W3: 3.2 | X3: 4.7
A4: 2023 | B4: =_xlfn.XLOOKUP(C4,ID!$J$2:$J$3825,ID!$I$2:$I$3825,"n/a",0,1) -> 24770 | C4: James Outman | D4: LAD | E4: 151 | F4: 567 | G4: 23 | H4: 86 | I4: 70 | J4: 16 | K4: 0.12 | L4: 0.319 | M4: 0.188 | N4: 0.343 | O4: 0.248 | P4: 0.353 | Q4: 0.437 | R4: 0.344 | S4: 0.324 | T4: 117 | U4: 3.4 | V4: 15.1 | W4: 4.7 | X4: 3.9
A5: 2023 | B5: =_xlfn.XLOOKUP(C5,ID!$J$2:$J$3825,ID!$I$2:$I$3825,"n/a",0,1) -> 20529 | C5: Nolan Jones | D5: COL | E5: 106 | F5: 424 | G5: 20 | H5: 60 | I5: 62 | J5: 20 | K5: 0.125 | L5: 0.297 | M5: 0.245 | N5: 0.401 | O5: 0.297 | P5: 0.389 | Q5: 0.542 | R5: 0.395 | S5: 0.362 | T5: 137 | U5: 2.1 | V5: 21.3 | W5: 1.6 | X5: 3.7
A6: 2023 | B6: =_xlfn.XLOOKUP(C6,ID!$J$2:$J$3825,ID!$I$2:$I$3825,"n/a",0,1) -> 29695 | C6: Matt McLain | D6: CIN | E6: 89 | F6: 403 | G6: 16 | H6: 65 | I6: 50 | J6: 14 | K6: 0.077 | L6: 0.285 | M6: 0.216 | N6: 0.385 | O6: 0.29 | P6: 0.357 | Q6: 0.507 | R6: 0.37 | S6: 0.332 | T6: 129 | U6: 0.4 | V6: 14.7 | W6: 3.7 | X6: 3.2
A7: 2023 | B7: =_xlfn.XLOOKUP(C7,ID!$J$2:$J$3825,ID!$I$2:$I$3825,"n/a",0,1) -> 26121 | C7: Francisco Alvarez | D7: NYM | E7: 123 | F7: 423 | G7: 25 | H7: 51 | I7: 63 | J7: 2 | K7: 0.08 | L7: 0.26 | M7: 0.228 | N7: 0.222 | O7: 0.209 | P7: 0.284 | Q7: 0.437 | R7: 0.31 | S7: 0.306 | T7: 96 | U7: -2.8 | V7: -4.8 | W7: 20.1 | X7: 3
A8: 2023 | B8: =_xlfn.XLOOKUP(C8,ID!$J$2:$J$3825,ID!$I$2:$I$3825,"n/a",0,1) -> n/a | C8: Josh Jung | D8: TEX | E8: 122 | F8: 515 | G8: 23 | H8: 75 | I8: 70 | J8: 1 | K8: 0.058 | L8: 0.293 | M8: 0.201 | N8: 0.34 | O8: 0.266 | P8: 0.315 | Q8: 0.467 | R8: 0.334 | S8: 0.334 | T8: 114 | U8: -3.4 | V8: 5.2 | W8: 5.4 | X8: 2.8
A9: 2023 | B9: =_xlfn.XLOOKUP(C9,ID!$J$2:$J$3825,ID!$I$2:$I$3825,"n/a",0,1) -> 29766 | C9: Zack Gelof | D9: OAK | E9: 69 | F9: 300 | G9: 14 | H9: 40 | I9: 32 | J9: 14 | K9: 0.087 | L9: 0.273 | M9: 0.237 | N9: 0.331 | O9: 0.267 | P9: 0.337 | Q9: 0.504 | R9: 0.357 | S9: 0.33 | T9: 132 | U9: 2.2 | V9: 13.8 | W9: 3 | X9: 2.7
A10: 2023 | B10: =_xlfn.XLOOKUP(C10,ID!$J$2:$J$3825,ID!$I$2:$I$3825,"n/a",0,1) -> 27534 | C10: Edouard Julien | D10: MIN | E10: 109 | F10: 408 | G10: 16 | H10: 60 | I10: 37 | J10: 3 | K10: 0.157 | L10: 0.314 | M10: 0.195 | N10: 0.371 | O10: 0.263 | P10: 0.381 | Q10: 0.459 | R10: 0.366 | S10: 0.343 | T10: 134 | U10: -1.2 | V10: 15.4 | W10: -2.4 | X10: 2.7
A11: 2023 | B11: =_xlfn.XLOOKUP(C11,ID!$J$2:$J$3825,ID!$I$2:$I$3825,"n/a",0,1) -> 27478 | C11: Patrick Bailey | D11: SFG | E11: 97 | F11: 353 | G11: 7 | H11: 29 | I11: 48 | J11: 1 | K11: 0.059 | L11: 0.283 | M11: 0.126 | N11: 0.314 | O11: 0.233 | P11: 0.285 | Q11: 0.359 | R11: 0.282 | S11: 0.312 | T11: 77 | U11: -0.3 | V11: -10.6 | W11: 25.5 | X11: 2.7
A12: 2023 | B12: =_xlfn.XLOOKUP(C12,ID!$J$2:$J$3825,ID!$I$2:$I$3825,"n/a",0,1) -> 19354 | C12: Luke Raley | D12: TBR | E12: 118 | F12: 406 | G12: 19 | H12: 56 | I12: 49 | J12: 14 | K12: 0.069 | L12: 0.315 | M12: 0.241 | N12: 0.33 | O12: 0.249 | P12: 0.333 | Q12: 0.49 | R12: 0.353 | S12: 0.328 | T12: 129 | U12: 2 | V12: 16.2 | W12: -5.6 | X12: 2.4
A13: 2023 | B13: =_xlfn.XLOOKUP(C13,ID!$J$2:$J$3825,ID!$I$2:$I$3825,"n/a",0,1) -> 23003 | C13: Yainer Diaz | D13: HOU | E13: 104 | F13: 377 | G13: 23 | H13: 51 | I13: 60 | J13: 0 | K13: 0.029 | L13: 0.196 | M13: 0.256 | N13: 0.292 | O13: 0.282 | P13: 0.308 | Q13: 0.538 | R13: 0.354 | S13: 0.358 | T13: 127 | U13: -1.7 | V13: 10.3 | W13: 1.1 | X13: 2.4
... A626: 2021 | B626: =_xlfn.XLOOKUP(C626,ID!$J$2:$J$3825,ID!$I$2:$I$3825,"n/a",0,1) -> 19903 | C626: Adonis Medina | D626: PHI | E626: 4 | F626: 1 | G626: 0 | H626: 0 | I626: 0 | J626: 0 | K626: 0 | L626: 1 | M626: 0 | N626: 0 | O626: 0 | P626: 0 | Q626: 0 | R626: 0 | S626: 0 | T626: -100 | U626: 0 | V626: -0.3 | W626: 0.1 | X626: 0
A627: 2021 | B627: =_xlfn.XLOOKUP(C627,ID!$J$2:$J$3825,ID!$I$2:$I$3825,"n/a",0,1) -> n/a | C627: Ramón Rosso | D627: PHI | E627: 7 | F627: 1 | G627: 0 | H627: 0 | I627: 0 | J627: 0 | K627: 0 | L627: 0 | M627: 0 | N627: 0 | O627: 0 | P627: 0 | Q627: 0 | R627: 0 | T627: -100 | U627: 0 | V627: -0.3 | W627: 0.1 | X627: 0
A628: 2021 | B628: =_xlfn.XLOOKUP(C628,ID!$J$2:$J$3825,ID!$I$2:$I$3825,"n/a",0,1) -> n/a | C628: Hans Crouse | D628: PHI | E628: 2 | F628: 1 | G628: 0 | H628: 0 | I628: 0 | J628: 0 | K628: 0 | L628: 1 | M628: 0 | N628: 0 | O628: 0 | P628: 0 | Q628: 0 | R628: 0 | S628: 0 | T628: -100 | U628: 0 | V628: -0.3 | W628: 0.1 | X628: 0
A629: 2021 | B629: =_xlfn.XLOOKUP(C629,ID!$J$2:$J$3825,ID!$I$2:$I$3825,"n/a",0,1) -> 21524 | C629: Joey Bart | D629: SFG | E629: 2 | F629: 6 | G629: 0 | H629: 1 | I629: 1 | J629: 0 | K629: 0 | L629: 0.333 | M629: 0 | N629: 0.5 | O629: 0.333 | P629: 0.333 | Q629: 0.333 | R629: 0.293 | S629: 0.321 | T629: 85 | U629: 0 | V629: -0.1 | W629: -0.2 | X629: 0
A630: 2021 | B630: =_xlfn.XLOOKUP(C630,ID!$J$2:$J$3825,ID!$I$2:$I$3825,"n/a",0,1) -> 16291 | C630: Nick Ciuffo | D630: BAL | E630: 2 | F630: 6 | G630: 0 | H630: 0 | I630: 0 | J630: 0 | K630: 0.167 | L630: 0.167 | M630: 0.2 | N630: 0.25 | O630: 0.2 | P630: 0.333 | Q630: 0.4 | R630: 0.322 | S630: 0.275 | T630: 102 | U630: 0.1 | V630: 0.1 | W630: -0.4 | X630: 0
A631: 2021 | B631: =_xlfn.XLOOKUP(C631,ID!$J$2:$J$3825,ID!$I$2:$I$3825,"n/a",0,1) -> 19569 | C631: David Bednar | D631: PIT | E631: 61 | F631: 1 | G631: 0 | H631: 0 | I631: 0 | J631: 0 | K631: 0 | L631: 1 | M631: 0 | N631: 0 | O631: 0 | P631: 0 | Q631: 0 | R631: 0 | S631: 0 | T631: -100 | U631: 0 | V631: -0.3 | W631: 0.1 | X631: 0
A632: 2021 | B632: =_xlfn.XLOOKUP(C632,ID!$J$2:$J$3825,ID!$I$2:$I$3825,"n/a",0,1) -> n/a | C632: Sean Poppen | D632: 3 Tms | E632: 24 | F632: 1 | G632: 0 | H632: 0 | I632: 0 | J632: 0 | K632: 0 | L632: 1 | M632: 0 | N632: 0 | O632: 0 | P632: 0 | Q632: 0 | R632: 0 | S632: 0 | T632: -100 | U632: 0 | V632: -0.3 | W632: 0.1 | X632: 0
A633: 2021 | B633: =_xlfn.XLOOKUP(C633,ID!$J$2:$J$3825,ID!$I$2:$I$3825,"n/a",0,1) -> 25376 | C633: Nick Mears | D633: PIT | E633: 30 | F633: 1 | G633: 0 | H633: 0 | I633: 0 | J633: 0 | K633: 0 | L633: 1 | M633: 0 | N633: 0 | O633: 0 | P633: 0 | Q633: 0 | R633: 0 | S633: 0 | T633: -100 | U633: 0 | V633: -0.3 | W633: 0.1 | X633: 0
A634: 2021 | B634: =_xlfn.XLOOKUP(C634,ID!$J$2:$J$3825,ID!$I$2:$I$3825,"n/a",0,1) -> 19879 | C634: Tanner Houck | D634: BOS | E634: 18 | F634: 1 | G634: 0 | H634: 0 | I634: 0 | J634: 0 | K634: 0 | L634: 1 | M634: 0 | N634: 0 | O634: 0 | P634: 0 | Q634: 0 | R634: 0 | S634: 0 | T634: -100 | U634: 0 | V634: -0.3 | W634: 0.1 | X634: 0
A635: 2021 | B635: =_xlfn.XLOOKUP(C635,ID!$J$2:$J$3825,ID!$I$2:$I$3825,"n/a",0,1) -> n/a | C635: R.J. Alaniz | D635: CIN | E635: 3 | F635: 1 | G635: 0 | H635: 0 | I635: 0 | J635: 0 | K635: 0 | L635: 1 | M635: 0 | N635: 0 | O635: 0 | P635: 0 | Q635: 0 | R635: 0 | S635: 0 | T635: -100 | U635: 0 | V635: -0.3 | W635: 0.1 | X635: 0
A636: 2021 | B636: =_xlfn.XLOOKUP(C636,ID!$J$2:$J$3825,ID!$I$2:$I$3825,"n/a",0,1) -> n/a | C636: Ryan Hendrix | D636: CIN | E636: 36 | F636: 1 | G636: 0 | H636: 0 | I636: 0 | J636: 0 | K636: 0 | L636: 0 | M636: 0 | N636: 0 | O636: 0 | P636: 0 | Q636: 0 | R636: 0 | S636: 0.229 | T636: -100 | U636: 0 | V636: -0.3 | W636: 0.1 | X636: 0
A637: 2021 | B637: =_xlfn.XLOOKUP(C637,ID!$J$2:$J$3825,ID!$I$2:$I$3825,"n/a",0,1) -> 16377 | C637: Ryan Castellani | D637: COL | E637: 1 | F637: 1 | G637: 0 | H637: 0 | I637: 0 | J637: 0 | K637: 0 | L637: 0 | M637: 0 | N637: 0 | O637: 0 | P637: 0 | Q637: 0 | R637: 0 | S637: 0.128 | T637: -100 | U637: 0 | V637: -0.3 | W637: 0.1 | X637: 0
A638: 2021 | B638: =_xlfn.XLOOKUP(C638,ID!$J$2:$J$3825,ID!$I$2:$I$3825,"n/a",0,1) -> 21446 | C638: Ryan Feltner | D638: COL | E638: 2 | F638: 1 | G638: 0 | H638: 0 | I638: 0 | J638: 0 | K638: 0 | L638: 1 | M638: 0 | N638: 0 | O638: 0 | P638: 0 | Q638: 0 | R638: 0 | S638: 0 | T638: -100 | U638: 0 | V638: -0.3 | W638: 0.1 | X638: 0
A639: 2021 | B639: =_xlfn.XLOOKUP(C639,ID!$J$2:$J$3825,ID!$I$2:$I$3825,"n/a",0,1) -> 20302 | C639: David Peterson | D639: NYM | E639: 16 | F639: 20 | G639: 0 | H639: 2 | I639: 0 | J639: 0 | K639: 0 | L639: 0.5 | M639: 0.063 | N639: 0.167 | O639: 0.063 | P639: 0.118 | Q639: 0.125 | R639: 0.116 | S639: 0.114 | T639: -30 | U639: 0.1 | V639: -3.2 | W639: 2.4 | X639: 0
... A1078: 2019 | B1078: =_xlfn.XLOOKUP(C1078,ID!$J$2:$J$3825,ID!$I$2:$I$3825,"n/a",0,1) -> 17982 | C1078: Ty France | D1078: SDP | E1078: 69 | F1078: 201 | G1078: 7 | H1078: 20 | I1078: 24 | J1078: 0 | K1078: 0.045 | L1078: 0.244 | M1078: 0.168 | N1078: 0.279 | O1078: 0.234 | P1078: 0.294 | Q1078: 0.402 | R1078: 0.296 | S1078: 0.294 | T1078: 84 | U1078: -1.4 | V1078: -5.7 | W1078: -0.8 | X1078: 0
A1079: 2019 | B1079: =_xlfn.XLOOKUP(C1079,ID!$J$2:$J$3825,ID!$I$2:$I$3825,"n/a",0,1) -> n/a | C1079: Matt Carasiti | D1079: SEA | E1079: 11 | F1079: 1 | G1079: 0 | H1079: 0 | I1079: 0 | J1079: 0 | K1079: 0 | L1079: 0 | M1079: 0 | N1079: 0 | O1079: 0 | P1079: 0 | Q1079: 0 | R1079: 0 | T1079: -100 | U1079: 0 | V1079: -0.3 | W1079: 0.1 | X1079: 0
A1080: 2019 | B1080: =_xlfn.XLOOKUP(C1080,ID!$J$2:$J$3825,ID!$I$2:$I$3825,"n/a",0,1) -> 13801 | C1080: Austin Adams | D1080: 2 Tms | E1080: 30 | F1080: 1 | G1080: 0 | H1080: 0 | I1080: 0 | J1080: 0 | K1080: 0 | L1080: 1 | M1080: 0 | N1080: 0 | O1080: 0 | P1080: 0 | Q1080: 0 | R1080: 0 | S1080: 0 | T1080: -100 | U1080: 0 | V1080: -0.3 | W1080: 0.1 | X1080: 0
A1081: 2019 | B1081: =_xlfn.XLOOKUP(C1081,ID!$J$2:$J$3825,ID!$I$2:$I$3825,"n/a",0,1) -> 19268 | C1081: Justin Dunn | D1081: SEA | E1081: 4 | F1081: 1 | G1081: 0 | H1081: 0 | I1081: 0 | J1081: 0 | K1081: 0 | L1081: 1 | M1081: 0 | N1081: 0 | O1081: 0 | P1081: 0 | Q1081: 0 | R1081: 0 | S1081: 0 | T1081: -100 | U1081: 0 | V1081: -0.3 | W1081: 0.1 | X1081: 0
A1082: 2019 | B1082: =_xlfn.XLOOKUP(C1082,ID!$J$2:$J$3825,ID!$I$2:$I$3825,"n/a",0,1) -> n/a | C1082: Tanner Anderson | D1082: OAK | E1082: 6 | F1082: 1 | G1082: 0 | H1082: 0 | I1082: 0 | J1082: 0 | K1082: 0 | L1082: 1 | M1082: 0 | N1082: 0 | O1082: 0 | P1082: 0 | Q1082: 0 | R1082: 0 | S1082: 0 | T1082: -100 | U1082: 0 | V1082: -0.3 | W1082: 0.1 | X1082: 0
A1083: 2019 | B1083: =_xlfn.XLOOKUP(C1083,ID!$J$2:$J$3825,ID!$I$2:$I$3825,"n/a",0,1) -> 17034 | C1083: Sean Reid-Foley | D1083: TOR | E1083: 9 | F1083: 1 | G1083: 0 | H1083: 0 | I1083: 0 | J1083: 0 | K1083: 0 | L1083: 1 | M1083: 0 | N1083: 0 | O1083: 0 | P1083: 0 | Q1083: 0 | R1083: 0 | S1083: 0 | T1083: -100 | U1083: 0 | V1083: -0.3 | W1083: 0.1 | X1083: 0
A1084: 2019 | B1084: =_xlfn.XLOOKUP(C1084,ID!$J$2:$J$3825,ID!$I$2:$I$3825,"n/a",0,1) -> 19269 | C1084: T.J. Zeuch | D1084: TOR | E1084: 5 | F1084: 1 | G1084: 0 | H1084: 0 | I1084: 0 | J1084: 0 | K1084: 0 | L1084: 1 | M1084: 0 | N1084: 0 | O1084: 0 | P1084: 0 | Q1084: 0 | R1084: 0 | S1084: 0 | T1084: -100 | U1084: 0 | V1084: -0.3 | W1084: 0.1 | X1084: 0
A1085: 2019 | B1085: =_xlfn.XLOOKUP(C1085,ID!$J$2:$J$3825,ID!$I$2:$I$3825,"n/a",0,1) -> 20632 | C1085: Elvis Luciano | D1085: TOR | E1085: 25 | F1085: 1 | G1085: 0 | H1085: 0 | I1085: 0 | J1085: 0 | K1085: 0 | L1085: 1 | M1085: 0 | N1085: 0 | O1085: 0 | P1085: 0 | Q1085: 0 | R1085: 0 | S1085: 0 | T1085: -100 | U1085: 0 | V1085: -0.3 | W1085: 0.1 | X1085: 0
A1086: 2019 | B1086: =_xlfn.XLOOKUP(C1086,ID!$J$2:$J$3825,ID!$I$2:$I$3825,"n/a",0,1) -> 15690 | C1086: Jimmy Cordero | D1086: 2 Tms | E1086: 31 | F1086: 1 | G1086: 0 | H1086: 0 | I1086: 0 | J1086: 0 | K1086: 0 | L1086: 0 | M1086: 0 | N1086: 0 | O1086: 0 | P1086: 0 | Q1086: 0 | R1086: 0 | T1086: -100 | U1086: 0 | V1086: -0.3 | W1086: 0.1 | X1086: 0
A1087: 2019 | B1087: =_xlfn.XLOOKUP(C1087,ID!$J$2:$J$3825,ID!$I$2:$I$3825,"n/a",0,1) -> 19979 | C1087: Zach Plesac | D1087: CLE | E1087: 21 | F1087: 1 | G1087: 0 | H1087: 0 | I1087: 0 | J1087: 0 | K1087: 0 | L1087: 0 | M1087: 0 | N1087: 0 | O1087: 0 | P1087: 0 | Q1087: 0 | R1087: 0 | T1087: -100 | U1087: 0 | V1087: -0.3 | W1087: 0.1 | X1087: 0
A1088: 2019 | B1088: =_xlfn.XLOOKUP(C1088,ID!$J$2:$J$3825,ID!$I$2:$I$3825,"n/a",0,1) -> 12575 | C1088: Nick Ramirez | D1088: DET | E1088: 46 | F1088: 1 | G1088: 0 | H1088: 0 | I1088: 0 | J1088: 0 | K1088: 0 | L1088: 1 | M1088: 0 | N1088: 0 | O1088: 0 | P1088: 0 | Q1088: 0 | R1088: 0 | S1088: 0 | T1088: -100 | U1088: 0 | V1088: -0.3 | W1088: 0.1 | X1088: 0
A1089: 2019 | B1089: =_xlfn.XLOOKUP(C1089,ID!$J$2:$J$3825,ID!$I$2:$I$3825,"n/a",0,1) -> 16631 | C1089: Jeff Brigham | D1089: MIA | E1089: 32 | F1089: 1 | G1089: 0 | H1089: 0 | I1089: 0 | J1089: 0 | K1089: 0 | L1089: 1 | M1089: 0 | N1089: 0 | O1089: 0 | P1089: 0 | Q1089: 0 | R1089: 0 | S1089: 0 | T1089: -100 | U1089: 0 | V1089: -0.3 | W1089: 0.1 | X1089: 0
A1090: 2019 | B1090: =_xlfn.XLOOKUP(C1090,ID!$J$2:$J$3825,ID!$I$2:$I$3825,"n/a",0,1) -> 18297 | C1090: Tyler Kinley | D1090: MIA | E1090: 52 | F1090: 1 | G1090: 0 | H1090: 0 | I1090: 0 | J1090: 0 | K1090: 0 | L1090: 1 | M1090: 0 | N1090: 0 | O1090: 0 | P1090: 0 | Q1090: 0 | R1090: 0 | S1090: 0 | T1090: -100 | U1090: 0 | V1090: -0.3 | W1090: 0.1 | X1090: 0
...

Sheet ID
A1: IDPLAYER | B1: PLAYERNAME | C1: BIRTHDATE | D1: FIRSTNAME | E1: LASTNAME | F1: TEAM | G1: LG | H1: POS | I1: IDFANGRAPHS | J1: FANGRAPHSNAME | K1: MLBID | L1: MLBNAME | M1: CBSID | N1: CBSNAME | O1: RETROID | P1: BREFID | Q1: NFBCID | R1: NFBCNAME | S1: ESPNID | T1: ESPNNAME | U1: KFFLNAME | V1: DAVENPORTID | W1: BPID | X1: YAHOOID | Y1: YAHOONAME | Z1: MSTRBLLNAME | AA1: BATS | AB1: THROWS | AC1: FANTPROSNAME | AD1: LASTCOMMAFIRST | AE1: ROTOWIREID | AF1: FANDUELNAME | AG1: FANDUELID | AH1: DRAFTKINGSNAME | AI1: OTTONEUID | AJ1: HQID | AK1: RAZZBALLNAME | AL1: FANTRAXID | AM1: FANTRAXNAME | AN1: ROTOWIRENAME | AO1: ALLPOS | AP1: NFBCLASTFIRST | AQ1: ACTIVE | AR1: UNDERDOG | AS1: RAZZBALLID
A2: aardsda01 | B2: David Aardsma | C2: 29947 | D2: David | E2: Aardsma | F2: N/A | G2: N/A | H2: P | I2: 1902 | J2: David Aardsma | K2: 430911 | L2: David Aardsma | M2: 479025 | N2: David Aardsma | O2: aardd001 | P2: aardsda01 | R2: David Aardsma | S2: 5933 | T2: David Aardsma | V2: AARDSMA19811227A | W2: 45369 | X2: 7307 | Y2: David Aardsma | Z2: Aardsma, David | AA2: R | AB2: R | AC2: David Aardsma | AD2: Aardsma, David | AE2: 7633 | AH2: David Aardsma | AI2: 4362 | AK2: David Aardsma | AM2: David Aardsma | AN2: David Aardsma | AO2: P | AP2: Aardsma, David | AQ2: N
A3: abadfe01 | B3: Fernando Abad | C3: 31398 | D3: Fernando | E3: Abad | F3: COL | G3: NL | H3: P | I3: 4994 | J3: Fernando Abad | K3: 472551 | L3: Fernando Abad | M3: 1723564 | N3: Fernando Abad | O3: abadf001 | P3: abadfe01 | Q3: 7932 | R3: Fernando Abad | S3: 30417 | T3: Fernando Abad | V3: ABAD19851217A | W3: 49706 | X3: 8767 | Y3: Fernando Abad | Z3: Abad, Fernando | AA3: L | AB3: L | AC3: Fernando Abad | AD3: Abad, Fernando | AE3: 11285 | AF3: Fernando Abad | AG3: 12453 | AH3: Fernando Abad | AI3: 7372 | AJ3: 3556 | AK3: Fernando Abad | AL3: *01viz* | AM3: Fernando Abad | AN3: Fernando Abad | AO3: P | AP3: Abad, Fernando | AQ3: N | AR3: 344ab5df-3d83-410a-9ba7-76f12fc69779 | AS3: 4994
A4: abbotan01 | B4: Andrew Abbott | C4: 36312 | D4: Andrew | E4: Abbott | F4: CIN | G4: NL | H4: P | I4: 29911 | J4: Andrew Abbott | K4: 671096 | L4: Andrew Abbott | M4: 2836515 | N4: Andrew Abbott | O4: abboa001 | P4: abbotan01 | Q4: 11802 | R4: Andrew Abbott | S4: 4414528 | T4: Andrew Abbott | V4: ABBOTT19990601A | W4: 111327 | X4: 12395 | Y4: Andrew Abbott | AA4: L | AB4: L | AC4: Andrew Abbott | AD4: Abbott, Andrew | AE4: 16805 | AI4: 40607 | AJ4: 7179 | AK4: Andrew Abbott | AL4: *05jq2* | AM4: Andrew Abbott | AN4: Andrew Abbott | AO4: SP | AP4: Abbott, Andrew | AQ4: Y | AR4: 8b1f18bf-f4ec-4de5-876a-9e38f533601a | AS4: 671096
A5: abbotco01 | B5: Cory Abbott | C5: 34962 | D5: Cory | E5: Abbott | F5: SEA | G5: AL | H5: P | I5: 20277 | J5: Cory Abbott | K5: 676265 | L5: Cory Abbott | M5: 3116181 | N5: Cory Abbott | O5: abboc001 | P5: abbotco01 | Q5: 10790 | R5: Cory Abbott | S5: 41328 | T5: Cory Abbott | V5: ABBOTT19950920A | W5: 111166 | X5: 11435 | Y5: Cory Abbott | Z5: Abbott, Cory | AA5: R | AB5: R | AC5: Cory Abbott | AD5: Abbott, Cory | AE5: 14996 | AI5: 27184 | AJ5: 6286 | AK5: Cory Abbott | AL5: *04ef6* | AM5: Cory Abbott | AN5: Cory Abbott | AO5: P | AP5: Abbott, Cory | AQ5: Y | AR5: cc172e35-3d27-41ef-b65e-b37d9635deae | AS5: 676265
A6: abelmi01 | B6: Mick Abel | C6: 37121 | D6: Mick | E6: Abel | F6: MIN | G6: AL | H6: P | I6: 27756 | J6: Mick Abel | K6: 690953 | L6: Mick Abel | M6: 26615392 | N6: Mick Abel | O6: abelm001 | P6: abelmi01 | Q6: 11632 | R6: Mick Abel | S6: 4718970 | T6: Mick Abel | V6: ABEL20010818A | W6: 147751 | X6: 12166 | Y6: Mick Abel | AA6: R | AB6: R | AC6: Mick Abel | AD6: Abel, Mick | AE6: 16679 | AI6: 38330 | AJ6: 7268 | AK6: Mick Abel | AL6: *05g4k* | AM6: Mick Abel | AN6: Mick Abel | AO6: P | AP6: Abel, Mick | AQ6: Y | AR6: 6151ffe0-7851-4593-9466-e1b0b8b4bad4 | AS6: 690953
A7: abramcj01 | B7: CJ Abrams | C7: 36802 | D7: CJ | E7: Abrams | F7: WAS | G7: NL | H7: SS | I7: 25768 | J7: CJ Abrams | K7: 682928 | L7: CJ Abrams | M7: 3117475 | N7: C.J. Abrams | O7: abrac001 | P7: abramcj01 | Q7: 11045 | R7: CJ Abrams | S7: 42402 | T7: CJ Abrams | V7: ABRAMS20001003A | W7: 111352 | X7: 11822 | Y7: CJ Abrams | Z7: Abrams, CJ | AA7: L | AB7: R | AC7: CJ Abrams | AD7: Abrams, CJ | AE7: 16042 | AI7: 36922 | AJ7: 6791 | AK7: CJ Abrams | AL7: *04qk8* | AM7: CJ Abrams | AN7: CJ Abrams | AO7: SS | AP7: Abrams, CJ | AQ7: Y | AR7: beec0d4a-ed73-489b-80f1-3b811a071db9 | AS7: 682928
A8: abreual01 | B8: Albert Abreu | C8: 34968 | D8: Albert | E8: Abreu | F8: CIN | G8: NL | H8: SS | I8: 17485 | J8: Albert Abreu | K8: 656061 | L8: Albert Abreu | M8: 2211792 | N8: Albert Abreu | O8: abrea001 | P8: abreual01 | Q8: 9895 | R8: Albert Abreu | S8: 36041 | T8: Albert Abreu | V8: ABREU19950926A | W8: 104651 | X8: 10546 | Y8: Albert Abreu | Z8: Abreu, Albert | AA8: R | AB8: R | AC8: Albert Abreu | AD8: Abreu, Albert | AE8: 14063 | AI8: 20720 | AJ8: 5762 | AK8: Albert Abreu | AL8: *03xy4* | AM8: Albert Abreu | AN8: Albert Abreu | AO8: SS | AP8: Abreu, Albert | AQ8: Y | AR8: 1ca19d52-0c24-499a-8138-9410db0d8c58
A9: abreubo01 | B9: Bobby Abreu | C9: 27099 | D9: Bobby | E9: Abreu | F9: N/A | G9: N/A | H9: OF | I9: 945 | J9: Bobby Abreu | K9: 110029 | L9: Bobby Abreu | M9: 7367 | N9: Bobby Abreu | O9: abreb001 | P9: abreubo01 | R9: Bobby Abreu | S9: 3537 | T9: Bobby Abreu | U9: Bobby Abreu | V9: ABREU19740311A | W9: 650 | X9: 5698 | Y9: Bobby Abreu | Z9: Abreu, Bobby | AA9: L | AB9: R | AC9: Bobby Abreu | AD9: Abreu, Bobby | AI9: 8984 | AK9: Bobby Abreu | AM9: Bobby Abreu | AN9: Bobby Abreu | AO9: OF | AP9: Abreu, Bobby | AQ9: N
A10: abreubr01 | B10: Bryan Abreu | C10: 35542 | D10: Bryan | E10: Abreu | F10: HOU | G10: AL | H10: P | I10: 16609 | J10: Bryan Abreu | K10: 650556 | L10: Bryan Abreu | M10: 3055522 | N10: Bryan Abreu | O10: abreb002 | P10: abreubr01 | Q10: 10381 | R10: Bryan Abreu | S10: 41208 | T10: Bryan Abreu | V10: ABREU19970422A | W10: 104258 | X10: 11208 | Y10: Bryan Abreu | Z10: Abreu, Bryan | AA10: R | AB10: R | AC10: Bryan Abreu | AD10: Abreu, Bryan | AE10: 15744 | AI10: 20900 | AJ10: 6034 | AK10: Bryan Abreu | AL10: *04tlv* | AM10: Bryan Abreu | AN10: Bryan Abreu | AO10: RP | AP10: Abreu, Bryan | AQ10: Y | AR10: 89da4ba9-7145-40d7-8d7d-8064ce33b3e2 | AS10: 650556
A11: abreujo02 | B11: Jose Abreu | C11: 31806 | D11: Jose | E11: Abreu | F11: N/A | G11: N/A | H11: 1B | I11: 15676 | J11: Jose Abreu | K11: 547989 | L11: Jose Abreu | M11: 2106364 | N11: Jose Abreu | O11: abrej003 | P11: abreujo02 | Q11: 8626 | R11: Jose Abreu | S11: 33095 | T11: Jose Abreu | U11: Jose Abreu | V11: ABREUcubaJ01 | W11: 102005 | X11: 9540 | Y11: Jose Abreu | Z11: Abreu, Jose | AA11: R | AB11: R | AC11: Jose Abreu | AD11: Abreu, Jose | AE11: 11341 | AF11: Jose Abreu | AG11: 49523 | AH11: Jose Abreu | AI11: 18286 | AJ11: 4515 | AK11: Jose Abreu | AL11: *02i2e* | AM11: Jose Abreu | AN11: Jose Abreu | AO11: 1B | AP11: Abreu, Jose | AQ11: N | AR11: c57d78f5-d6fe-4369-8aa0-a9e68a4d2084 | AS11: 15676
A12: abreuto01 | B12: Tony Abreu | C12: 30999 | D12: Tony | E12: Abreu | F12: N/A | G12: N/A | H12: 2B | I12: 5053 | J12: Tony Abreu | K12: 473234 | L12: Tony Abreu | M12: 593265 | N12: Tony Abreu | O12: abret001 | P12: abreuto01 | R12: Tony Abreu | S12: 28777 | T12: Tony Abreu | U12: Tony Abreu | V12: ABREU19841113A | W12: 46923 | X12: 8033 | Y12: Tony Abreu | Z12: Abreu, Tony | AA12: B | AB12: R | AC12: Tony Abreu | AD12: Abreu, Tony | AE12: 9244 | AI12: 549 | AK12: Tony Abreu | AL12: *0002e* | AM12: Tony Abreu | AN12: Tony Abreu | AO12: 2B | AP12: Abreu, Tony | AQ12: N
A13: abreuwi02 | B13: Wilyer Abreu | C13: 36335 | D13: Wilyer | E13: Abreu | F13: BOS | G13: AL | H13: OF | I13: 23772 | J13: Wilyer Abreu | K13: 677800 | L13: Wilyer Abreu | M13: 28838043 | N13: Wilyer Abreu | O13: abrew002 | P13: abreuwi02 | Q13: 11709 | R13: Wilyer Abreu | S13: 4990055 | T13: Wilyer Abreu | V13: ABREU19990624A | W13: 111086 | X13: 12731 | Y13: Wilyer Abreu | AA13: L | AB13: L | AC13: Wilyer Abreu | AD13: Abreu, Wilyer | AE13: 17794 | AI13: 27058 | AJ13: 7815 | AK13: Wilyer Abreu | AL13: *060x1* | AM13: Wilyer Abreu | AN13: Wilyer Abreu | AO13: OF | AP13: Abreu, Wilyer | AQ13: Y | AR13: d8928609-98b5-45f8-80ef-b90c5c6b27f8 | AS13: 677800
A14: accarje01 | B14: Jeremy Accardo | C14: 29938 | D14: Jeremy | E14: Accardo | F14: N/A | G14: N/A | H14: P | I14: 6428 | J14: Jeremy Accardo | K14: 435618 | L14: Jeremy Accardo | M14: 490429 | N14: Jeremy Accardo | O14: accaj001 | P14: accarje01 | R14: Jeremy Accardo | S14: 6262 | T14: Jeremy Accardo | V14: ACCARDO19811208A | W14: 45614 | X14: 7534 | Y14: Jeremy Accardo | Z14: Accardo, Jeremy | AA14: R | AB14: R | AC14: Jeremy Accardo | AD14: Accardo, Jeremy | AI14: 8034 | AK14: Jeremy Accardo | AL14: *000ge* | AM14: Jeremy Accardo | AN14: Jeremy Accardo | AO14: P | AP14: Accardo, Jeremy | AQ14: N
A15: aceveal01 | B15: Alfredo Aceves | C15: 30293 | D15: Alfredo | E15: Aceves | F15: N/A | G15: N/A | H15: P | I15: 5164 | J15: Alfredo Aceves | K15: 469686 | L15: Alfredo Aceves | M15: 1638980 | N15: Alfredo Aceves | O15: aceva001 | P15: aceveal01 | R15: Alfredo Aceves | S15: 29223 | T15: Alfredo Aceves | V15: ACEVES19821208A | W15: 46928 | X15: 8336 | Y15: Alfredo Aceves | Z15: Aceves, Alfredo | AA15: R | AB15: R | AC15: Alfredo Aceves | AD15: Aceves, Alfredo | AE15: 10464 | AI15: 580 | AK15: Alfredo Aceves | AM15: Alfredo Aceves | AN15: Alfredo Aceves | AO15: P | AP15: Aceves, Alfredo | AQ15: N
A16: acevedo01 | B16: Domingo Acevedo | C16: 34399 | D16: Domingo | E16: Acevedo | F16: ATH | G16: AL | H16: P | I16: 17092 | J16: Domingo Acevedo | K16: 642758 | L16: Domingo Acevedo | M16: 2211789 | N16: Domingo Acevedo | O16: acevd001 | P16: acevedo01 | Q16: 9896 | R16: Domingo Acevedo | S16: 35010 | T16: Domingo Acevedo | V16: ACEVEDO19940603A | W16: 103250 | X16: 10545 | Y16: Domingo Acevedo | Z16: Acevedo, Domingo | AA16: R | AB16: R | AC16: Domingo Acevedo | AD16: Acevedo, Domingo | AE16: 14060 | AI16: 20032 | AJ16: 5763 | AK16: Domingo Acevedo | AL16: *03bam* | AM16: Domingo Acevedo | AN16: Domingo Acevedo | AO16: P | AP16: Acevedo, Domingo | AQ16: Y | AR16: af1275bf-b16e-4329-83de-383bea6c3c32 | AS16: 642758
A17: ackledu01 | B17: Dustin Ackley | C17: 32199 | D17: Dustin | E17: Ackley | F17: SEA | G17: AL | H17: 1B | I17: 10099 | J17: Dustin Ackley | K17: 554429 | L17: Dustin Ackley | M17: 1699742 | N17: Dustin Ackley | O17: ackld001 | P17: ackledu01 | R17: Dustin Ackley | S17: 30372 | T17: Dustin Ackley | U17: Dustin Ackley | V17: ACKLEY19880226A | W17: 61057 | X17: 8648 | Y17: Dustin Ackley | Z17: Ackley, Dustin | AA17: L | AB17: R | AC17: Dustin Ackley | AD17: Ackley, Dustin | AE17: 10944 | AF17: Dustin Ackley | AG17: 12853 | AH17: Dustin Ackley | AI17: 5141 | AJ17: 3375 | AK17: Dustin Ackley | AL17: *01fhn* | AM17: Dustin Ackley | AN17: Dustin Ackley | AO17: 1B | AP17: Ackley, Dustin | AQ17: N
A18: acostma01 | B18: Maximo Acosta | C18: 37558 | D18: Maximo | E18: Acosta | F18: MIA | G18: NL | H18: SS | I18: 27963 | J18: Maximo Acosta | K18: 691185 | L18: Maximo Acosta | N18: Maximo Acosta | O18: acosm001 | P18: acostma02 | Q18: 12290 | R18: Maximo Acosta | T18: Maximo Acosta | V18: ACOSTA20021029A | Y18: Maximo Acosta | Z18: Maximo Acosta | AA18: R | AB18: R | AC18: Maximo Acosta | AD18: Acosta, Maximo | AE18: 16348 | AF18: Maximo Acosta | AH18: Maximo Acosta | AJ18: 8381 | AK18: Maximo Acosta | AL18: *0568a* | AM18: Maximo Acosta | AN18: Maximo Acosta | AO18: SS | AP18: Acosta, Maximo | AQ18: Y | AR18: d9be8c85-21f4-4798-8df9-fca8d5724f6e | AS18: 691185
A19: actonga01 | B19: Garrett Acton | C19: 35961 | D19: Garrett | E19: Acton | F19: TB | G19: AL | H19: P | I19: 27583 | J19: Garrett Acton | K19: 670183 | L19: Garrett Acton | M19: 29084569 | N19: Garrett Acton | O19: actog001 | P19: actonga01 | Q19: 11759 | R19: Garrett Acton | S19: 4424444 | T19: Garrett Acton | V19: ACTON19980615A | W19: 111459 | X19: 61900 | Y19: Garrett Acton | AA19: L | AB19: R | AC19: Garrett Acton | AD19: Acton, Garrett | AE19: 17058 | AI19: 38539 | AJ19: 7318 | AK19: Garrett Acton | AL19: *05ybh* | AM19: Garrett Acton | AN19: Garrett Acton | AO19: P | AP19: Acton, Garrett | AQ19: Y | AR19: 6a08077a-df3d-45c9-a1b2-68e55049328b | AS19: 670183
A20: acunalu01 | B20: Luisangel Acuna | C20: 37327 | D20: Luisangel | E20: Acuna | F20: NYM | G20: NL | H20: SS | I20: 26548 | J20: Luisangel Acuna | K20: 682668 | L20: Luisangel Acuna | M20: 26615344 | N20: Luisangel Acuna | O20: acunl001 | P20: acunajo01 | Q20: 11614 | R20: Luisangel Acuna | T20: Luisangel Acuna | V20: ACUNA20020312A | W20: 111462 | Y20: Luisangel Acuna | AA20: R | AB20: R | AC20: Luisangel Acuna | AD20: Acuna, Luisangel | AE20: 16302 | AI20: 36048 | AJ20: 7855 | AK20: Luisangel Acuna | AL20: *04z6k* | AM20: Luisangel Jose Acuna | AN20: Luisangel Acuna | AO20: SS | AP20: Acuna, Luisangel | AQ20: Y | AR20: eaad3760-3954-4c5d-a82b-63983fed1f4c | AS20: 682668
A21: acunaro01 | B21: Ronald Acuna | C21: 35782 | D21: Ronald | E21: Acuna | F21: ATL | G21: NL | H21: OF | I21: 18401 | J21: Ronald Acuna Jr. | K21: 660670 | L21: Ronald Acuna | M21: 2211777 | N21: Ronald Acuna | O21: acunr001 | P21: acunaro01 | Q21: 9775 | R21: Ronald Acuna Jr. | S21: 36185 | T21: Ronald Acuna | V21: ACUNA19971218A | W21: 105454 | X21: 10646 | Y21: Ronald Acuna Jr. | Z21: Acuna Jr., Ronald | AA21: R | AB21: R | AC21: Ronald Acuna Jr. | AD21: Acuna, Ronald | AE21: 14200 | AI21: 23327 | AJ21: 5588 | AK21: Ronald Acuna Jr. | AL21: *03wha* | AM21: Ronald Acuna Jr. | AN21: Ronald Acuna | AO21: OF | AP21: Acuna Jr., Ronald | AQ21: Y | AR21: 0313642a-1e49-4c9f-8daa-79f2f440865d | AS21: 660670
A22: adamecr01 | B22: Cristhian Adames | C22: 33445 | D22: Cristhian | E22: Adames | F22: SF | G22: NL | H22: 2B | I22: 6013 | J22: Cristhian Adames | K22: 542436 | L22: Cristhian Adames | M22: 1959299 | N22: Cristhian Adames | O22: adamc001 | P22: adamecr01 | Q22: 8855 | R22: Cristhian Adames | S22: 31659 | T22: Cristhian Adames | V22: ADAMES19910726A | W22: 59755 | X22: 9774 | Y22: Cristhian Adames | Z22: Adames, Cristhian | AA22: B | AB22: R | AC22: Cristhian Adames | AD22: Adames, Cristhian | AE22: 11817 | AF22: Cristhian Adames | AG22: 21582 | AH22: Cristhian Adames | AI22: 10307 | AJ22: 4701 | AK22: Cristhian Adames | AL22: *027j7* | AM22: Cristhian Adames | AN22: Cristhian Adames | AO22: 2B | AP22: Adames, Cristhian | AQ22: N
A23: adamewi01 | B23: Willy Adames | C23: 34944 | D23: Willy | E23: Adames | F23: SF | G23: NL | H23: SS | I23: 15986 | J23: Willy Adames | K23: 642715 | L23: Willy Adames | M23: 2165933 | N23: Willy Adames | O23: adamw002 | P23: adamewi01 | Q23: 8971 | R23: Willy Adames | S23: 33675 | T23: Willy Adames | V23: ADAMES19950902A | W23: 103209 | X23: 9893 | Y23: Willy Adames | Z23: Adames, Willy | AA23: R | AB23: R | AC23: Willy Adames | AD23: Adames, Willy | AE23: 13593 | AH23: Willy Adames | AI23: 18407 | AJ23: 5053 | AK23: Willy Adames | AL23: *03atq* | AM23: Willy Adames | AN23: Willy Adames | AO23: SS | AP23: Adames, Willy | AQ23: Y | AR23: 6eb26750-b70f-4aa0-9f5f-da18f81f6d4b | AS23: 642715
A24: adamja01 | B24: Jason Adam | C24: 33454 | D24: Jason | E24: Adam | F24: SD | G24: NL | H24: P | I24: 11861 | J24: Jason Adam | K24: 592094 | L24: Jason Adam | M24: 1846226 | N24: Jason Adam | O24: adamj002 | P24: adamja01 | Q24: 10025 | R24: Jason Adam | S24: 32145 | T24: Jason Adam | V24: ADAM19910804A | W24: 68490 | X24: 11009 | Y24: Jason Adam | Z24: Adam, Jason | AA24: R | AB24: R | AC24: Jason Adam | AD24: Adam, Jason | AE24: 11588 | AF24: Jason Adam | AH24: Jason Adam | AI24: 27723 | AJ24: 5875 | AK24: Jason Adam | AL24: *025it* | AM24: Jason Adam | AN24: Jason Adam | AO24: RP | AP24: Adam, Jason | AQ24: Y | AR24: 54fad8c4-3974-4c09-99f6-c264e054dcd8 | AS24: 592094
A25: adamsau02 | B25: Austin Adams | C25: 33363 | D25: Austin | E25: Adams | F25: BOS | G25: AL | H25: P | I25: 13801 | J25: Austin Adams | K25: 613534 | L25: Austin Adams | M25: 2444539 | N25: Austin Adams | O25: adama002 | P25: adamsau02 | Q25: 9531 | R25: Austin Adams | S25: 31660 | T25: Austin Adams | V25: ADAMS19910505A | W25: 59978 | X25: 10760 | Y25: Austin L. Adams | Z25: Adams, Austin L. | AA25: R | AB25: R | AC25: Austin Adams | AD25: Adams, Austin | AE25: 14614 | AF25: Austin Adams | AH25: Austin Adams | AI25: 30529 | AJ25: 5652 | AK25: Austin Adams | AL25: *02h8x* | AM25: Austin Adams | AN25: Austin Adams | AO25: RP | AP25: Adams, Austin | AQ25: Y | AR25: 116527e4-cb64-4725-9210-9c0dd2d89b89 | AS25: 613534
A26: adamsch01 | B26: Chance Adams | C26: 34556 | D26: Chance | E26: Adams | F26: KC | G26: AL | H26: P | I26: 18135 | J26: Chance Adams | K26: 664856 | L26: Chance Adams | M26: 2449975 | N26: Chance Adams | O26: adamc002 | P26: adamsch01 | Q26: 9780 | R26: Chance Adams | S26: 36160 | T26: Chance Adams | V26: ADAMS19940810A | W26: 105455 | X26: 10541 | Y26: Chance Adams | Z26: Adams, Chance | AA26: R | AB26: R | AC26: Chance Adams | AD26: Adams, Chance | AE26: 14548 | AI26: 22738 | AJ26: 5647 | AK26: Chance Adams | AL26: *03qle* | AM26: Chance Adams | AN26: Chance Adams | AO26: P | AP26: Adams, Chance | AQ26: N | AS26: 664856
A27: adamsda02 | B27: David Adams | C27: 31912 | D27: David | E27: Adams | F27: N/A | G27: N/A | H27: 2B | I27: 7389 | J27: David Adams | K27: 458691 | L27: David Adams | M27: 1740903 | N27: David Adams | O27: adamd001 | P27: adamsda02 | R27: David Adams | S27: 30679 | T27: David Adams | U27: David Adams | V27: ADAMS19870515A | W27: 58003 | X27: 9395 | Y27: David Adams | Z27: Adams, David | AA27: R | AB27: R | AC27: David Adams | AD27: Adams, David | AE27: 10562 | AI27: 5335 | AK27: David Adams | AL27: *01sgs* | AM27: David Adams | AN27: David Adams | AO27: 2B | AP27: Adams, David | AQ27: N
A28: adamsla01 | B28: Lane Adams | C28: 32825 | D28: Lane | E28: Adams | F28: ATL | G28: NL | H28: OF | I28: 10767 | J28: Lane Adams | K28: 572669 | L28: Lane Adams | M28: 2048786 | N28: Lane Adams | O28: adaml001 | P28: adamsla01 | Q28: 8885 | R28: Lane Adams | S28: 32911 | T28: Lane Adams | V28: ADAMS19891113A | W28: 60150 | X28: 9806 | Y28: Lane Adams | Z28: Adams, Lane | AA28: R | AB28: R | AC28: Lane Adams | AD28: Adams, Lane | AE28: 13223 | AH28: Lane Adams | AI28: 12380 | AJ28: 4741 | AK28: Lane Adams | AL28: *02hce* | AM28: Lane Adams | AN28: Lane Adams | AO28: OF | AP28: Adams, Lane | AQ28: N
A29: adamsma01 | B29: Matt Adams | C29: 32386 | D29: Matt | E29: Adams | F29: WAS | G29: NL | H29: DH | I29: 9393 | J29: Matt Adams | K29: 571431 | L29: Matt Adams | M29: 1810388 | N29: Matt Adams | O29: adamm002 | P29: adamsma01 | Q29: 8214 | R29: Matt Adams | S29: 31359 | T29: Matt Adams | U29: Matt Adams | V29: ADAMS19880831A | W29: 59582 | X29: 9100 | Y29: Matt Adams | Z29: Adams, Matt | AA29: L | AB29: R | AC29: Matt Adams | AD29: Adams, Matt | AE29: 11977 | AF29: Matt Adams | AG29: 13799 | AH29: Matt Adams | AI29: 6302 | AJ29: 4003 | AK29: Matt Adams | AL29: *0272u* | AM29: Matt Adams | AN29: Matt Adams | AO29: DH | AP29: Adams, Matt | AQ29: N
A30: adamsmi03 | B30: Mike Adams | C30: 28700 | D30: Mike | E30: Adams | F30: N/A | G30: N/A | H30: P | I30: 1937 | J30: Mike Adams | K30: 430606 | L30: Mike Adams | M30: 392251 | N30: Mike Adams | O30: adamm102 | P30: adamsmi03 | R30: Mike Adams | S30: 5969 | T30: Mike Adams | V30: ADAMS19480724A | W30: 18328 | X30: 7332 | Y30: Mike Adams | Z30: Adams, Mike | AA30: R | AB30: R | AC30: Mike Adams | AD30: Adams, Mike | AI30: 3799 | AK30: Mike Adams | AL30: *005i9* | AM30: Mike Adams | AN30: Mike Adams | AO30: P | AP30: Adams, Mike | AQ30: N
A31: adamsri03 | B31: Riley Adams | C31: 35242 | D31: Riley | E31: Adams | F31: WAS | G31: NL | H31: C | I31: 19864 | J31: Riley Adams | K31: 656180 | L31: Riley Adams | M31: 2836521 | N31: Riley Adams | O31: adamr004 | P31: adamsri03 | Q31: 10850 | R31: Riley Adams | S31: 40655 | T31: Riley Adams | V31: ADAMS19960626A | W31: 109294 | X31: 11997 | Y31: Riley Adams | Z31: Adams, Riley | AA31: R | AB31: R | AC31: Riley Adams | AD31: Adams, Riley | AE31: 14832 | AI31: 31564 | AJ31: 6408 | AK31: Riley Adams | AL31: *04azt* | AM31: Riley Adams | AN31: Riley Adams | AO31: C | AP31: Adams, Riley | AQ31: Y | AR31: 571dd37a-6c05-460a-8c51-6f7508d080f0 | AS31: 656180
A32: adamssp03 | B32: Spencer Adams | C32: 35168 | D32: Spencer | E32: Adams | F32: CHW | G32: AL | H32: P | J32: Spencer Adams | K32: 656181 | L32: Spencer Adams | M32: 2167472 | N32: Spencer Adams | P32: adamssp03 | S32: 33779 | T32: Spencer Adams | V32: ADAMS19960413A | W32: 104717 | X32: 10449 | Y32: Spencer Adams | Z32: Adams, Spencer | AA32: R | AB32: R | AC32: Spencer Adams | AD32: Adams, Spencer | AE32: 13390 | AJ32: 6027 | AK32: Spencer Adams | AL32: *03d77* | AM32: Spencer Adams | AN32: Spencer Adams | AO32: P | AQ32: N
A33: adducji02 | B33: Jim Adduci | C33: 31182 | D33: Jim | E33: Adduci | F33: CHC | G33: NL | H33: OF | I33: 6448 | J33: Jim Adduci | K33: 451192 | L33: Jim Adduci | M33: 549732 | N33: Jim Adduci | O33: adduj002 | P33: adducji02 | Q33: 8597 | R33: Jim Adduci | S33: 30019 | T33: Jim Adduci | V33: ADDUCI19850515A | W33: 46943 | X33: 9512 | Y33: Jim Adduci | Z33: Adduci, Jim | AA33: L | AB33: L | AC33: Jim Adduci | AD33: Adduci, Jim | AE33: 11299 | AH33: Jim Adduci | AI33: 1672 | AJ33: 4456 | AK33: Jim Adduci | AL33: *037y7* | AM33: Jim Adduci | AN33: Jim Adduci | AO33: OF | AP33: Adduci, Jim | AQ33: N
A34: adelljo01 | B34: Jo Adell | C34: 36258 | D34: Jo | E34: Adell | F34: LAA | G34: AL | H34: OF | I34: 20220 | J34: Jo Adell | K34: 666176 | L34: Jo Adell | M34: 2835062 | N34: Jo Adell | O34: adelj001 | P34: adelljo01 | Q34: 10241 | R34: Jo Adell | S34: 40854 | T34: Jo Adell | V34: ADELL19990408A | W34: 109295 | X34: 10893 | Y34: Jo Adell | Z34: Adell, Jo | AA34: R | AB34: R | AC34: Jo Adell | AD34: Adell, Jo | AE34: 14770 | AH34: Jo Adell | AI34: 23792 | AJ34: 6082 | AK34: Jo Adell | AL34: *04aee* | AM34: Jo Adell | AN34: Jo Adell | AO34: OF | AP34: Adell, Jo | AQ34: Y | AR34: 273b8042-63e2-4675-956e-37305cdbe006 | AS34: 666176
A35: adlemti01 | B35: Tim Adleman | C35: 32094 | D35: Tim | E35: Adleman | F35: N/A | G35: N/A | H35: P | I35: 10968 | J35: Tim Adleman | K35: 534947 | L35: Tim Adleman | M35: 2170252 | N35: Tim Adleman | O35: adlet001 | P35: adlemti01 | Q35: 9356 | R35: Tim Adleman | S35: 33962 | T35: Tim Adleman | V35: ADLEMAN19871113A | W35: 65945 | X35: 10282 | Y35: Tim Adleman | Z35: Adleman, Tim | AA35: R | AB35: R | AC35: Timothy Adleman | AD35: Adleman, Tim | AE35: 14208 | AF35: Tim Adleman | AG35: 70351 | AH35: Tim Adleman | AI35: 13610 | AJ35: 5261 | AK35: Tim Adleman | AL35: *040kr* | AM35: Tim Adleman | AN35: Tim Adleman | AO35: P | AP35: Adleman, Tim | AQ35: N
A36: adonjo01 | B36: Joan Adon | C36: 36019 | D36: Joan | E36: Adon | F36: WAS | G36: NL | H36: P | I36: 22925 | J36: Joan Adon | K36: 672851 | L36: Joan Adon | M36: 2829294 | N36: Joan Adon | O36: adonj001 | P36: adonjo01 | Q36: 10968 | R36: Joan Adon | S36: 4684360 | T36: Joan Adon | V36: ADON19980812A | W36: 109297 | X36: 11857 | Y36: Joan Adon | Z36: Adon, Joan | AA36: R | AB36: R | AC36: Joan Adon | AD36: Adon, Joan | AE36: 16030 | AF36: Joan Adon | AH36: Joan Adon | AI36: 25629 | AJ36: 6434 | AK36: Joan Adon | AL36: *04ywo* | AM36: Joan Adon | AN36: Joan Adon | AO36: RP | AP36: Adon, Joan | AQ36: Y | AR36: 2e59e623-30ba-4ae9-a63c-3956881a49f2 | AS36: 672851
A37: adriaeh01 | B37: Ehire Adrianza | C37: 32741 | D37: Ehire | E37: Adrianza | F37: LAA | G37: AL | H37: 3B | I37: 8418 | J37: Ehire Adrianza | K37: 501303 | L37: Ehire Adrianza | M37: 1666190 | N37: Ehire Adrianza | O37: adrie001 | P37: adriaeh01 | Q37: 8606 | R37: Ehire Adrianza | S37: 30471 | T37: Ehire Adrianza | V37: ADRIANZA19890821A | W37: 50677 | X37: 9521 | Y37: Ehire Adrianza | Z37: Adrianza, Ehire | AA37: B | AB37: R | AC37: Ehire Adrianza | AD37: Adrianza, Ehire | AE37: 10790 | AH37: Ehire Adrianza | AI37: 8445 | AJ37: 4466 | AK37: Ehire Adrianza | AL37: *01t3l* | AM37: Ehire Adrianza | AN37: Ehire Adrianza | AO37: 3B | AP37: Adrianza, Ehire | AQ37: N | AR37: 15261c81-80fe-4208-84ff-61bf96647609 | AS37: 8418
A38: affelje01 | B38: Jeremy Affeldt | C38: 29012 | D38: Jeremy | E38: Affeldt | F38: N/A | G38: N/A | H38: P | I38: 583 | J38: Jeremy Affeldt | K38: 346793 | L38: Jeremy Affeldt | M38: 223741 | N38: Jeremy Affeldt | O38: affej001 | P38: affelje01 | R38: Jeremy Affeldt | S38: 5061 | T38: Jeremy Affeldt | V38: AFFELDT19790606A | W38: 1354 | X38: 6883 | Y38: Jeremy Affeldt | Z38: Affeldt, Jeremy | AA38: L | AB38: L | AC38: Jeremy Affeldt | AD38: Affeldt, Jeremy | AE38: 6588 | AF38: Jeremy Affeldt | AG38: 5108 | AI38: 14848 | AK38: Jeremy Affeldt | AM38: Jeremy Affeldt | AN38: Jeremy Affeldt | AO38: P | AP38: Affeldt, Jeremy | AQ38: N
A39: agnosza01 | B39: Zach Agnos | C39: 36753 | D39: Zach | E39: Agnos | F39: COL | G39: NL | H39: P | I39: 31552 | J39: Zach Agnos | K39: 688642 | L39: Zach Agnos | N39: Zach Agnos | O39: agnoz001 | P39: agnosza01 | Q39: 12221 | R39: Zach Agnos | T39: Zach Agnos | V39: AGNOS20000815A | Y39: Zach Agnos | Z39: Zach Agnos | AA39: R | AB39: R | AC39: Zach Agnos | AD39: Agnos, Zach | AE39: 19812 | AF39: Zach Agnos | AH39: Zach Agnos | AJ39: 8228 | AK39: Zach Agnos | AL39: *064ny* | AM39: Zach Agnos | AN39: Zach Agnos | AO39: P | AP39: Agnos, Zach | AQ39: Y | AR39: 1a4545a9-b6de-4c0b-b2e5-2714c03f9924 | AS39: 688642
A40: agrazda01 | B40: Dario Agrazal | C40: 34696 | D40: Dario | E40: Agrazal | F40: DET | G40: AL | H40: P | I40: 15821 | J40: Dario Agrazal | K40: 642607 | L40: Dario Agrazal | M40: 2898220 | N40: Dario Agrazal | O40: agrad001 | P40: agrazda01 | Q40: 9849 | R40: Dario Agrazal | S40: 39813 | T40: Dario Agrazal | V40: AGRAZAL19941228A | W40: 103111 | X40: 11185 | Y40: Dario Agrazal | Z40: Agrazal, Dario | AA40: R | AB40: R | AC40: Dario Agrazal | AD40: Agrazal, Dario | AE40: 15247 | AJ40: 6169 | AK40: Dario Agrazal | AL40: *03z9y* | AM40: Dario Agrazal | AN40: Dario Agrazal | AO40: P | AP40: Agrazal, Dario | AQ40: N
...
